Workbook
Name _E4110: #REF!
Name a: #REF!
Name a1A32: [1]AD24101!$A$31
Name 出荷元: #REF!
Name 出荷方法: #REF!
Name 生地品番: [3]生地・色リスト!$A$2:$A$18
Name 色: [3]生地・色リスト!$C$2:$C$40

Sheet Dữ Liệu
B1: TAIYO NISSHIN VIETNAM CO.,LTD 太陽日新ベトナム株式会社
A2: P1. THÔNG TIN CHI TIẾT HÀNG HÓA 製品詳細
A3: 1 | B3: 2 | C3: 3 | D3: 4 | E3: 5 | F3: 6 | G3: 7 | H3: 8 | I3: 9 | J3: 10 | K3: GĐĐ | L3: TIỀN XE
A4: TÊN KHÁCH HÀNG | B4: NHÀ MÁY | C4: Mã hàng | D4: Thương hiệu | E4: Tên hàng | F4: Màu | G4: Size | H4: Số Lượng | I4: Ngày nhận | J4: Ngày xuất
A5: CUSTOMER | B5: FACTORY | C5: Style No | D5: Brand | E5: Item | F5: Color | G5: Size | H5: Quantity | I5: Date | J5: Date
A6: お客様 | B6: 工場 | C6: 品番 | D6: ブランド | E6: 品目 | F6: カラー | G6: サイズ | H6: サイズ | I6: サイズ | J6: サイズ
A7: TAMURAKOMA | B7: TPA | C7: BR1144 | D7: GUA | E7: SHIRT | F7: WH | H7: 100 | K7: 1 | L7: 650000 | M7: 100
A8: TAMURAKOMA | B8: TPA | C8: BR1109 | D8: GUA | E8: SHIRT | F8: WH | H8: 300
A9: TAMURAKOMA | B9: TPA | C9: BR9071 | D9: GUA | E9: SHIRT | F9: WH
A10: TAMURAKOMA | B10: TPA | C10: HS8078 | D10: GUA | E10: SHIRT | F10: WH
A11: TAMURAKOMA | B11: TPA | C11: BR1108 | D11: GUA | E11: SHIRT | F11: WH
A12: TAMURAKOMA | B12: TPA | C12: BR9125 | D12: GUA | E12: SHIRT | F12: WH
A13: TAMURAKOMA | B13: TPA | C13: BR9070 | D13: GUA | E13: SHIRT | F13: WH
A14: TAMURAKOMA | B14: TPA | C14: HS8073 | D14: GUA | E14: SHIRT | F14: WH
A15: TAMURAKOMA | B15: AA | C15: HS8072 | D15: SSK | E15: PANT | F15: BLACK | H15: 1000 | K15: 1.5 | L15: 800000

Sheet Daily Report
B1: TAIYO NISSHIN VIETNAM CO.,LTD 太陽日新ベトナム株式会社
A2: BÁO CÁO KẾT QUẢ KIỂM HÀNG 検品 結 果 報 告 書
A3: P1. THÔNG TIN CHI TIẾT HÀNG HÓA | H3: P2. BÁO CÁO KIỂM HÀNG CHI TIẾT HẰNG NGÀY | T3: P3. THEO DỎI NĂNG SUẤT
A4: Ngày kiểm hàng | B4: Nội dung kiểm hàng | C4: Mã hàng | D4: Thương hiệu | E4: Tên hàng | F4: Màu | G4: Size | H4: SL kiểm hàng | I4: Hàng đạt | J4: Hàng hư | K4: Thông số | L4: Phụ liệu | M4: Ngoại quan | N4: Vải | O4: Dơ | P4: Lổi may | Q4: Khác | R4: Kiểm Kim | S4: Tỉ lệ lỗi | T4: SL BOOK | U4: SL BOOK CHÊNH LỆCH | V4: SL QC | W4: GIỜ ĐI ĐƯỜNG | X4: THỜI GIAN LÀM VIỆC | Y4: THỜI GIAN TĂNG CA | Z4: MD | AA4: TỔ TRƯỞNG | AB4: ĐIỂM NĂNG SUẤT | AC4: GHI CHÚ
A5: Date | B5: Inspection | C5: Style No | D5: Brand | E5: Item | F5: Color | G5: Size | H5: Inspection Qty | I5: A-Grade Qty | J5: Defect Qty | K5: Measurment | L5: Material | M5: Appearance | N5: Fabric | O5: Dirt | P5: Sewing | Q5: Other | R5: Needle Inspection | S5: rate | T5: BOOKING Q'TY | U5: Q'TY DIFFERENCE | V5: QC Q'TY | X5: TIME | Y5: OT | Z5: MD | AA5: LEADER | AB5: PRODUCTIVITY SCORE | AC5: NOTE
A6: 日付 | B6: 検品内容 | C6: 品番 | D6: ブランド | E6: 品目 | F6: カラー | G6: サイズ | H6: 検品数 | I6: 良品数 | J6: 不良品数 | K6: 採寸不良 | L6: 付属不良 | M6: 外観不良 | N6: 生地不良 | O6: 汚れ不良 | P6: 縫製不良 | Q6: その他 | R6: 検針 | S6: 不良率 | T6: 予約数量 | U6: 数量差 | V6: 人数 | X6: 作業時間 | Y6: 残業時間 | Z6: 担当者 | AA6: リーダー
A7: 46086 | B7: KIEM | C7: BR1144 | D7: =IF(C7=" "," ",VLOOKUP(C7,'Dữ Liệu'!$C$7:$D$134,2,FALSE)) -> GUA | E7: SHIRT | F7: WH | G7: L | H7: 51 | I7: =H7-J7 -> 47 | J7: =SUM(K7:Q7) -> 4 | O7: 3 | P7: 1 | S7: =J7/H7 -> 0.078431373 | V7: 4 | W7: 1.5 | Y7: 1 | AD7: =C7&F7&G7&B7 -> BR1144WHLKIEM | AE7: =C7&F7&G7 -> BR1144WHL
A8: 46086 | B8: KIEM | C8: BR1144 | D8: =IF(C8=" "," ",VLOOKUP(C8,'Dữ Liệu'!$C$7:$D$134,2,FALSE)) -> GUA | E8: SHIRT | F8: WH | G8: LL | H8: 67 | I8: =H8-J8 -> 60 | J8: =SUM(K8:Q8) -> 7 | O8: 5 | P8: 2 | S8: =J8/H8 -> 0.10447761 | V8: 4 | W8: 1.5 | Y8: 1 | AD8: =C8&F8&G8&B8 -> BR1144WHLLKIEM | AE8: =C8&F8&G8 -> BR1144WHLL
A9: 46086 | B9: KIEM | C9: BR9071 | D9: =IF(C9=" "," ",VLOOKUP(C9,'Dữ Liệu'!$C$7:$D$134,2,FALSE)) -> GUA | E9: SHIRT | F9: WH | G9: M | H9: 114 | I9: =H9-J9 -> 102 | J9: =SUM(K9:Q9) -> 12 | O9: 9 | P9: 3 | S9: =J9/H9 -> 0.10526316 | V9: 4 | W9: 1.5 | Y9: 1 | AD9: =C9&F9&G9&B9 -> BR9071WHMKIEM | AE9: =C9&F9&G9 -> BR9071WHM
A10: 46086 | B10: KIEM | C10: HS8078 | D10: =IF(C10=" "," ",VLOOKUP(C10,'Dữ Liệu'!$C$7:$D$134,2,FALSE)) -> GUA | E10: SHIRT | F10: WH | G10: M | H10: 91 | I10: =H10-J10 -> 85 | J10: =SUM(K10:Q10) -> 6 | O10: 4 | P10: 2 | S10: =J10/H10 -> 0.065934066 | V10: 4 | W10: 1.5 | Y10: 1 | AD10: =C10&F10&G10&B10 -> HS8078WHMKIEM | AE10: =C10&F10&G10 -> HS8078WHM
A11: 46086 | B11: KIEM | C11: HS8078 | D11: =IF(C11=" "," ",VLOOKUP(C11,'Dữ Liệu'!$C$7:$D$134,2,FALSE)) -> GUA | E11: SHIRT | F11: WH | G11: L | H11: 111 | I11: =H11-J11 -> 101 | J11: =SUM(K11:Q11) -> 10 | O11: 6 | P11: 4 | S11: =J11/H11 -> 0.09009009 | V11: 4 | W11: 1.5 | Y11: 1 | AD11: =C11&F11&G11&B11 -> HS8078WHLKIEM | AE11: =C11&F11&G11 -> HS8078WHL
A12: 46086 | B12: KIEM | C12: HS8078 | D12: =IF(C12=" "," ",VLOOKUP(C12,'Dữ Liệu'!$C$7:$D$134,2,FALSE)) -> GUA | E12: SHIRT | F12: WH | G12: LL | H12: 66 | I12: =H12-J12 -> 63 | J12: =SUM(K12:Q12) -> 3 | O12: 2 | P12: 1 | S12: =J12/H12 -> 0.045454545 | V12: 4 | W12: 1.5 | Y12: 1 | AD12: =C12&F12&G12&B12 -> HS8078WHLLKIEM | AE12: =C12&F12&G12 -> HS8078WHLL
A13: 46086 | B13: KIEM | C13: BR9070 | D13: =IF(C13=" "," ",VLOOKUP(C13,'Dữ Liệu'!$C$7:$D$134,2,FALSE)) -> GUA | E13: SHIRT | F13: WH | G13: S | H13: 2 | I13: =H13-J13 -> 2 | J13: =SUM(K13:Q13) -> 0 | S13: =J13/H13 -> 0 | V13: 4 | W13: 1.5 | Y13: 1 | AD13: =C13&F13&G13&B13 -> BR9070WHSKIEM | AE13: =C13&F13&G13 -> BR9070WHS
A14: 46086 | B14: KIEM | C14: BR9070 | D14: =IF(C14=" "," ",VLOOKUP(C14,'Dữ Liệu'!$C$7:$D$134,2,FALSE)) -> GUA | E14: SHIRT | F14: WH | G14: M | H14: 2 | I14: =H14-J14 -> 2 | J14: =SUM(K14:Q14) -> 0 | S14: =J14/H14 -> 0 | AD14: =C14&F14&G14&B14 -> BR9070WHMKIEM | AE14: =C14&F14&G14 -> BR9070WHM
A15: 46086 | B15: KIEM | C15: BR9070 | D15: =IF(C15=" "," ",VLOOKUP(C15,'Dữ Liệu'!$C$7:$D$134,2,FALSE)) -> GUA | E15: SHIRT | F15: WH | G15: LL | H15: 1 | I15: =H15-J15 -> 1 | J15: =SUM(K15:Q15) -> 0 | S15: =J15/H15 -> 0 | AD15: =C15&F15&G15&B15 -> BR9070WHLLKIEM | AE15: =C15&F15&G15 -> BR9070WHLL
A16: 46086 | B16: KIEM | C16: HS8073 | D16: =IF(C16=" "," ",VLOOKUP(C16,'Dữ Liệu'!$C$7:$D$134,2,FALSE)) -> GUA | E16: SHIRT | F16: WH | G16: M | H16: 2 | I16: =H16-J16 -> 2 | J16: =SUM(K16:Q16) -> 0 | S16: =J16/H16 -> 0 | AD16: =C16&F16&G16&B16 -> HS8073WHMKIEM | AE16: =C16&F16&G16 -> HS8073WHM
A17: 46086 | B17: KIEM | C17: HS8073 | D17: =IF(C17=" "," ",VLOOKUP(C17,'Dữ Liệu'!$C$7:$D$134,2,FALSE)) -> GUA | E17: SHIRT | F17: WH | G17: L | H17: 1 | I17: =H17-J17 -> 1 | J17: =SUM(K17:Q17) -> 0 | S17: =J17/H17 -> 0 | AD17: =C17&F17&G17&B17 -> HS8073WHLKIEM | AE17: =C17&F17&G17 -> HS8073WHL
A18: 46086 | B18: KIEM | C18: BR1109 | D18: =IF(C18=" "," ",VLOOKUP(C18,'Dữ Liệu'!$C$7:$D$134,2,FALSE)) -> GUA | E18: SHIRT | F18: WH | G18: L | H18: 2 | I18: =H18-J18 -> 2 | J18: =SUM(K18:Q18) -> 0 | S18: =J18/H18 -> 0 | AD18: =C18&F18&G18&B18 -> BR1109WHLKIEM | AE18: =C18&F18&G18 -> BR1109WHL
A19: 46086 | B19: TAIKIEM | C19: BR1144 | D19: =IF(C19=" "," ",VLOOKUP(C19,'Dữ Liệu'!$C$7:$D$134,2,FALSE)) -> GUA | E19: SHIRT | F19: WH | G19: L | H19: 4 | I19: =H19-J19 -> 4 | J19: =SUM(K19:Q19) -> 0 | S19: =J19/H19 -> 0 | AD19: =C19&F19&G19&B19 -> BR1144WHLTAIKIEM | AE19: =C19&F19&G19 -> BR1144WHL
A20: 46086 | B20: TAIKIEM | C20: BR1144 | D20: =IF(C20=" "," ",VLOOKUP(C20,'Dữ Liệu'!$C$7:$D$134,2,FALSE)) -> GUA | E20: SHIRT | F20: WH | G20: LL | H20: 7 | I20: =H20-J20 -> 7 | J20: =SUM(K20:Q20) -> 0 | S20: =J20/H20 -> 0 | AD20: =C20&F20&G20&B20 -> BR1144WHLLTAIKIEM | AE20: =C20&F20&G20 -> BR1144WHLL
A21: 46086 | B21: TAIKIEM | C21: BR9071 | D21: =IF(C21=" "," ",VLOOKUP(C21,'Dữ Liệu'!$C$7:$D$134,2,FALSE)) -> GUA | E21: SHIRT | F21: WH | G21: M | H21: 12 | I21: =H21-J21 -> 12 | J21: =SUM(K21:Q21) -> 0 | S21: =J21/H21 -> 0 | AD21: =C21&F21&G21&B21 -> BR9071WHMTAIKIEM | AE21: =C21&F21&G21 -> BR9071WHM
A22: 46086 | B22: TAIKIEM | C22: HS8078 | D22: =IF(C22=" "," ",VLOOKUP(C22,'Dữ Liệu'!$C$7:$D$134,2,FALSE)) -> GUA | E22: SHIRT | F22: WH | G22: M | H22: 6 | I22: =H22-J22 -> 6 | J22: =SUM(K22:Q22) -> 0 | S22: =J22/H22 -> 0 | AD22: =C22&F22&G22&B22 -> HS8078WHMTAIKIEM | AE22: =C22&F22&G22 -> HS8078WHM
A23: 46086 | B23: TAIKIEM | C23: HS8078 | D23: =IF(C23=" "," ",VLOOKUP(C23,'Dữ Liệu'!$C$7:$D$134,2,FALSE)) -> GUA | E23: SHIRT | F23: WH | G23: L | H23: 10 | I23: =H23-J23 -> 10 | J23: =SUM(K23:Q23) -> 0 | S23: =J23/H23 -> 0 | AD23: =C23&F23&G23&B23 -> HS8078WHLTAIKIEM | AE23: =C23&F23&G23 -> HS8078WHL
A24: 46086 | B24: TAIKIEM | C24: HS8078 | D24: =IF(C24=" "," ",VLOOKUP(C24,'Dữ Liệu'!$C$7:$D$134,2,FALSE)) -> GUA | E24: SHIRT | F24: WH | G24: LL | H24: 3 | I24: =H24-J24 -> 3 | J24: =SUM(K24:Q24) -> 0 | S24: =J24/H24 -> 0 | AD24: =C24&F24&G24&B24 -> HS8078WHLLTAIKIEM | AE24: =C24&F24&G24 -> HS8078WHLL
A25: 46090 | B25: KIEM | C25: BR9071 | D25: =IF(C25=" "," ",VLOOKUP(C25,'Dữ Liệu'!$C$7:$D$134,2,FALSE)) -> GUA | E25: SHIRT | F25: WH | G25: S | H25: 100 | I25: =H25-J25 -> 89 | J25: =SUM(K25:Q25) -> 11 | O25: 9 | P25: 2 | S25: =J25/H25 -> 0.11 | AD25: =C25&F25&G25&B25 -> BR9071WHSKIEM | AE25: =C25&F25&G25 -> BR9071WHS
A26: 46090 | B26: KIEM | C26: BR9071 | D26: =IF(C26=" "," ",VLOOKUP(C26,'Dữ Liệu'!$C$7:$D$134,2,FALSE)) -> GUA | E26: SHIRT | F26: WH | G26: M | H26: 86 | I26: =H26-J26 -> 81 | J26: =SUM(K26:Q26) -> 5 | O26: 5 | S26: =J26/H26 -> 0.058139535 | AD26: =C26&F26&G26&B26 -> BR9071WHMKIEM | AE26: =C26&F26&G26 -> BR9071WHM
A27: 46090 | B27: KIEM | C27: BR9071 | D27: =IF(C27=" "," ",VLOOKUP(C27,'Dữ Liệu'!$C$7:$D$134,2,FALSE)) -> GUA | E27: SHIRT | F27: WH | G27: L | H27: 100 | I27: =H27-J27 -> 88 | J27: =SUM(K27:Q27) -> 12 | O27: 9 | P27: 3 | S27: =J27/H27 -> 0.12 | AD27: =C27&F27&G27&B27 -> BR9071WHLKIEM | AE27: =C27&F27&G27 -> BR9071WHL
A28: 46090 | B28: KIEM | C28: BR9071 | D28: =IF(C28=" "," ",VLOOKUP(C28,'Dữ Liệu'!$C$7:$D$134,2,FALSE)) -> GUA | E28: SHIRT | F28: WH | G28: LL | H28: 50 | I28: =H28-J28 -> 47 | J28: =SUM(K28:Q28) -> 3 | O28: 2 | P28: 1 | S28: =J28/H28 -> 0.06 | AD28: =C28&F28&G28&B28 -> BR9071WHLLKIEM | AE28: =C28&F28&G28 -> BR9071WHLL
A29: 46090 | B29: KIEM | C29: BR9071 | D29: =IF(C29=" "," ",VLOOKUP(C29,'Dữ Liệu'!$C$7:$D$134,2,FALSE)) -> GUA | E29: SHIRT | F29: WH | G29: EL | H29: 28 | I29: =H29-J29 -> 27 | J29: =SUM(K29:Q29) -> 1 | O29: 1 | S29: =J29/H29 -> 0.035714286 | AD29: =C29&F29&G29&B29 -> BR9071WHELKIEM | AE29: =C29&F29&G29 -> BR9071WHEL
A30: 46090 | B30: KIEM | C30: BR9071 | D30: =IF(C30=" "," ",VLOOKUP(C30,'Dữ Liệu'!$C$7:$D$134,2,FALSE)) -> GUA | E30: SHIRT | F30: WH | G30: 4L | H30: 20 | I30: =H30-J30 -> 19 | J30: =SUM(K30:Q30) -> 1 | O30: 1 | S30: =J30/H30 -> 0.05 | AD30: =C30&F30&G30&B30 -> BR9071WH4LKIEM | AE30: =C30&F30&G30 -> BR9071WH4L
A31: 46090 | B31: KIEM | C31: BR1144 | D31: =IF(C31=" "," ",VLOOKUP(C31,'Dữ Liệu'!$C$7:$D$134,2,FALSE)) -> GUA | E31: SHIRT | F31: WH | G31: LL | H31: 38 | I31: =H31-J31 -> 37 | J31: =SUM(K31:Q31) -> 1 | O31: 1 | S31: =J31/H31 -> 0.026315789 | AD31: =C31&F31&G31&B31 -> BR1144WHLLKIEM | AE31: =C31&F31&G31 -> BR1144WHLL
A32: 46090 | B32: TAIKIEM | C32: BR9071 | D32: =IF(C32=" "," ",VLOOKUP(C32,'Dữ Liệu'!$C$7:$D$134,2,FALSE)) -> GUA | E32: SHIRT | F32: WH | G32: S | H32: 11 | I32: =H32-J32 -> 11 | J32: =SUM(K32:Q32) -> 0 | S32: =J32/H32 -> 0 | AD32: =C32&F32&G32&B32 -> BR9071WHSTAIKIEM | AE32: =C32&F32&G32 -> BR9071WHS
A33: 46090 | B33: TAIKIEM | C33: BR9071 | D33: =IF(C33=" "," ",VLOOKUP(C33,'Dữ Liệu'!$C$7:$D$134,2,FALSE)) -> GUA | E33: SHIRT | F33: WH | G33: M | H33: 5 | I33: =H33-J33 -> 5 | J33: =SUM(K33:Q33) -> 0 | S33: =J33/H33 -> 0 | AD33: =C33&F33&G33&B33 -> BR9071WHMTAIKIEM | AE33: =C33&F33&G33 -> BR9071WHM
A34: 46090 | B34: TAIKIEM | C34: BR9071 | D34: =IF(C34=" "," ",VLOOKUP(C34,'Dữ Liệu'!$C$7:$D$134,2,FALSE)) -> GUA | E34: SHIRT | F34: WH | G34: L | H34: 12 | I34: =H34-J34 -> 12 | J34: =SUM(K34:Q34) -> 0 | S34: =J34/H34 -> 0 | AD34: =C34&F34&G34&B34 -> BR9071WHLTAIKIEM | AE34: =C34&F34&G34 -> BR9071WHL
A35: 46090 | B35: TAIKIEM | C35: BR9071 | D35: =IF(C35=" "," ",VLOOKUP(C35,'Dữ Liệu'!$C$7:$D$134,2,FALSE)) -> GUA | E35: SHIRT | F35: WH | G35: LL | H35: 3 | I35: =H35-J35 -> 3 | J35: =SUM(K35:Q35) -> 0 | S35: =J35/H35 -> 0 | AD35: =C35&F35&G35&B35 -> BR9071WHLLTAIKIEM | AE35: =C35&F35&G35 -> BR9071WHLL
A36: 46090 | B36: TAIKIEM | C36: BR9071 | D36: =IF(C36=" "," ",VLOOKUP(C36,'Dữ Liệu'!$C$7:$D$134,2,FALSE)) -> GUA | E36: SHIRT | F36: WH | G36: EL | H36: 1 | I36: =H36-J36 -> 1 | J36: =SUM(K36:Q36) -> 0 | S36: =J36/H36 -> 0 | AD36: =C36&F36&G36&B36 -> BR9071WHELTAIKIEM | AE36: =C36&F36&G36 -> BR9071WHEL
A37: 46090 | B37: TAIKIEM | C37: BR9071 | D37: =IF(C37=" "," ",VLOOKUP(C37,'Dữ Liệu'!$C$7:$D$134,2,FALSE)) -> GUA | E37: SHIRT | F37: WH | G37: 4L | H37: 1 | I37: =H37-J37 -> 1 | J37: =SUM(K37:Q37) -> 0 | S37: =J37/H37 -> 0 | AD37: =C37&F37&G37&B37 -> BR9071WH4LTAIKIEM | AE37: =C37&F37&G37 -> BR9071WH4L
A38: 46090 | B38: TAIKIEM | C38: BR1144 | D38: =IF(C38=" "," ",VLOOKUP(C38,'Dữ Liệu'!$C$7:$D$134,2,FALSE)) -> GUA | E38: SHIRT | F38: WH | G38: LL | H38: 1 | I38: =H38-J38 -> 1 | J38: =SUM(K38:Q38) -> 0 | S38: =J38/H38 -> 0 | AD38: =C38&F38&G38&B38 -> BR1144WHLLTAIKIEM | AE38: =C38&F38&G38 -> BR1144WHLL
A39: 46091 | B39: KIEM | C39: BR1144 | D39: =IF(C39=" "," ",VLOOKUP(C39,'Dữ Liệu'!$C$7:$D$134,2,FALSE)) -> GUA | E39: SHIRT | F39: WH | G39: SS | H39: 15 | I39: =H39-J39 -> 14 | J39: =SUM(K39:Q39) -> 1 | O39: 1 | S39: =J39/H39 -> 0.066666667 | AD39: =C39&F39&G39&B39 -> BR1144WHSSKIEM | AE39: =C39&F39&G39 -> BR1144WHSS
A40: 46091 | B40: KIEM | C40: BR1144 | D40: =IF(C40=" "," ",VLOOKUP(C40,'Dữ Liệu'!$C$7:$D$134,2,FALSE)) -> GUA | E40: SHIRT | F40: WH | G40: S | H40: 71 | I40: =H40-J40 -> 65 | J40: =SUM(K40:Q40) -> 6 | O40: 1 | P40: 5 | S40: =J40/H40 -> 0.084507042 | AD40: =C40&F40&G40&B40 -> BR1144WHSKIEM | AE40: =C40&F40&G40 -> BR1144WHS
...

Sheet Cumulative Table
A1: TAIYO NISSHIN VIETNAM CO.,LTD 太陽日新ベトナム株式会社
A2: BÁO CÁO KẾT QUẢ KIỂM HÀNG 検品 結 果 報 告 書
A3: 累計表(Cumulative Table)
A4: 品番 | B4: ブランド | C4: 品目 | D4: カラー | E4: サイズ | F4: ロット数 | G4: 検品数(初回検品のみ) | H4: 再検品数量(2回目以降の検査も含む) | I4: 良品数(初回・それ以降の検査分含む) | J4: 検針良品数(初回・それ以降の検査分含む) | K4: 出荷済み数量 | O4: Thông số | P4: Phụ liệu | Q4: Ngoại quan | R4: Vải | S4: Dơ | T4: Lổi may | U4: Khác | V4: Kiểm Kim | W4: Tỉ lệ lỗi
A5: Style No | B5: Brand | C5: Item | D5: Color | E5: Size | F5: Order Qty | G5: Inspection Qty | H5: Re-inspection Qty | I5: A-Grade Qty | J5: A-Grade Qty | K5: Shipment Qty | O5: Measurment | P5: Material | Q5: Appearance | R5: Fabric | S5: Dirt | T5: Sewing | U5: Other | V5: Needle Inspection | W5: rate | Y5: KIỂM | AF5: TỔNG NGÀY KIỂM
A6: Mã hàng | B6: Thương hiệu | C6: Tên hàng | D6: Màu | E6: Size | F6: Số lượng đơn hàng | G6: SL kiểm hàng | H6: SL tái kiểm | I6: SL Hàng đạt | J6: SL Hàng đạt Kiểm kim | K6: SL xuất 1 | L6: SL xuất 2 | M6: SL xuất 3 | N6: TỔNG XUẤT | O6: 採寸不良 | P6: 付属不良 | Q6: 外観不良 | R6: 生地不良 | S6: 汚れ不良 | T6: 縫製不良 | U6: その他 | V6: 検針 | W6: 不良率 | Y6: NGÀY 2026/03/05 | AA6: NGÀY 2026/03/09 | AC6: NGÀY 2026/03/10 | AE6: 2026/03/05 - 03/10 | AF6: NGÀY BẮT ĐẦU | AG6: NGÀY KẾT THÚC | AH6: TỔNG SỐ HÀNG KIỂM | AI6: TỔNG SỐ HÀNG TÁI
A7: BR9125 | B7: =VLOOKUP($A7,'Daily Report'!$C$7:$E$263,2,FALSE) -> GUA | C7: =VLOOKUP($A7,'Daily Report'!$C$7:$E$263,3,FALSE) -> SHIRT | D7: WH | E7: SS | F7: =SUMIF('Dữ Liệu'!#REF!,'Cumulative Table'!$X7,'Dữ Liệu'!$H$7:$H$134) -> #REF! | G7: =SUMIF('Daily Report'!$AD$7:$AD$263,'Cumulative Table'!$X7&"KIEM",'Daily Report'!$H$7:$H$263) -> 0 | H7: =SUMIF('Daily Report'!$AD$7:$AD$263,'Cumulative Table'!$X7&"TAIKIEM",'Daily Report'!$H$7:$H$263) -> 0 | I7: =SUMIF('Daily Report'!$AE$7:$AE$263,'Cumulative Table'!$X7,'Daily Report'!$I$7:$I$263) -> 0 | J7: =SUMIF('Daily Report'!AE7:AE263,'Cumulative Table'!X7:X201,'Daily Report'!R7:R263) -> 0 | N7: =SUM(K7:M7) -> 0 | O7: =SUMIF('Daily Report'!$AE$7:$AE$263,'Cumulative Table'!$X7,'Daily Report'!$K$7:$K$263) -> 0 | P7: =SUMIF('Daily Report'!$AE$7:$AE$263,'Cumulative Table'!$X7,'Daily Report'!$L$7:$L$263) -> 0 | Q7: =SUMIF('Daily Report'!$AE$7:$AE$263,'Cumulative Table'!$X7,'Daily Report'!$M$7:$M$263) -> 0 | R7: =SUMIF('Daily Report'!$AE$7:$AE$263,'Cumulative Table'!$X7,'Daily Report'!$N$7:$N$263) -> 0 | S7: =SUMIF('Daily Report'!$AE$7:$AE$263,'Cumulative Table'!$X7,'Daily Report'!$O$7:$O$263) -> 0 | T7: =SUMIF('Daily Report'!$AE$7:$AE$263,'Cumulative Table'!$X7,'Daily Report'!$P$7:$P$263) -> 0 | U7: =SUMIF('Daily Report'!$AE$7:$AE$263,'Cumulative Table'!$X7,'Daily Report'!$Q$7:$Q$263) -> 0 | W7: =H7/G7 -> #DIV/0! | X7: =A$7&D7&E7 -> BR9125WHSS | Y7: 46095 | Z7: =SUMIFS('Daily Report'!$H$7:$H$263, 'Daily Report'!$AD$7:$AD$263, $X7&"KIEM", 'Daily Report'!$A$7:$A$263, $Y$7) -> 0 | AA7: 46096 | AB7: =SUMIFS('Daily Report'!$H$7:$H$200,'Daily Report'!$AD$7:$AD$200,'Cumulative Table'!$X7&"KIEM",'Daily Report'!$A$7:$A$200,'Cumulative Table'!$AA$7) -> 0 | AC7: 46097 | AD7: =SUMIFS('Daily Report'!$H$7:$H$200,'Daily Report'!$AD$7:$AD$200,'Cumulative Table'!$X7&"KIEM",'Daily Report'!$A$7:$A$200,'Cumulative Table'!$AC$7) -> 0 | AE7: =SUMIFS('Daily Report'!$H$7:$H$200,'Daily Report'!$AD$7:$AD$200,'Cumulative Table'!$X7&"KIEM",'Daily Report'!$A$7:$A$200,">="&'Cumulative Table'!$Y$7,'Daily Report'!$A$7:$A$200,"<="&'Cumulative Table'!$AC$7) -> 0 | AF7: 46095 | AG7: 46097 | AH7: =SUMIFS('Daily Report'!$H$7:$H$200,'Daily Report'!$AD$7:$AD$200,'Cumulative Table'!$X7&"KIEM",'Daily Report'!$A$7:$A$200,">="&'Cumulative Table'!$AF$7,'Daily Report'!$A$7:$A$200,"<="&'Cumulative Table'!$AG$7) -> 0 | AI7: =SUMIFS('Daily Report'!$H$7:$H$200,'Daily Report'!$AD$7:$AD$200,'Cumulative Table'!$X7&"TAIKIEM",'Daily Report'!$A$7:$A$200,">="&'Cumulative Table'!$AF$7,'Daily Report'!$A$7:$A$200,"<="&'Cumulative Table'!$AG$7) -> 0
D8: WH | E8: S | F8: =SUMIF('Dữ Liệu'!#REF!,'Cumulative Table'!$X8,'Dữ Liệu'!$H$7:$H$134) -> #REF! | G8: =SUMIF('Daily Report'!$AD$7:$AD$263,'Cumulative Table'!$X8&"KIEM",'Daily Report'!$H$7:$H$263) -> 133 | H8: =SUMIF('Daily Report'!$AD$7:$AD$263,'Cumulative Table'!$X8&"TAIKIEM",'Daily Report'!$H$7:$H$263) -> 18 | I8: =SUMIF('Daily Report'!$AE$7:$AE$263,'Cumulative Table'!$X8,'Daily Report'!$I$7:$I$263) -> 133 | J8: =SUMIF('Daily Report'!AE8:AE264,'Cumulative Table'!X8:X202,'Daily Report'!R8:R264) -> 0 | N8: =SUM(K8:M8) -> 0 | O8: =SUMIF('Daily Report'!$AE$7:$AE$263,'Cumulative Table'!$X8,'Daily Report'!$K$7:$K$263) -> 0 | P8: =SUMIF('Daily Report'!$AE$7:$AE$263,'Cumulative Table'!$X8,'Daily Report'!$L$7:$L$263) -> 0 | Q8: =SUMIF('Daily Report'!$AE$7:$AE$263,'Cumulative Table'!$X8,'Daily Report'!$M$7:$M$263) -> 2 | R8: =SUMIF('Daily Report'!$AE$7:$AE$263,'Cumulative Table'!$X8,'Daily Report'!$N$7:$N$263) -> 0 | S8: =SUMIF('Daily Report'!$AE$7:$AE$263,'Cumulative Table'!$X8,'Daily Report'!$O$7:$O$263) -> 12 | T8: =SUMIF('Daily Report'!$AE$7:$AE$263,'Cumulative Table'!$X8,'Daily Report'!$P$7:$P$263) -> 4 | U8: =SUMIF('Daily Report'!$AE$7:$AE$263,'Cumulative Table'!$X8,'Daily Report'!$Q$7:$Q$263) -> 0 | W8: =H8/G8 -> 0.13533835 | X8: =A$7&D8&E8 -> BR9125WHS | Z8: =SUMIFS('Daily Report'!$H$7:$H$263, 'Daily Report'!$AD$7:$AD$263, $X8&"KIEM", 'Daily Report'!$A$7:$A$263, $Y$7) -> 0 | AB8: =SUMIFS('Daily Report'!$H$7:$H$200,'Daily Report'!$AD$7:$AD$200,'Cumulative Table'!$X8&"KIEM",'Daily Report'!$A$7:$A$200,'Cumulative Table'!$AA$7) -> 0 | AD8: =SUMIFS('Daily Report'!$H$7:$H$200,'Daily Report'!$AD$7:$AD$200,'Cumulative Table'!$X8&"KIEM",'Daily Report'!$A$7:$A$200,'Cumulative Table'!$AC$7) -> 133 | AE8: =SUMIFS('Daily Report'!$H$7:$H$200,'Daily Report'!$AD$7:$AD$200,'Cumulative Table'!$X8&"KIEM",'Daily Report'!$A$7:$A$200,">="&'Cumulative Table'!$Y$7,'Daily Report'!$A$7:$A$200,"<="&'Cumulative Table'!$AC$7) -> 133 | AH8: =SUMIFS('Daily Report'!$H$7:$H$200,'Daily Report'!$AD$7:$AD$200,'Cumulative Table'!$X8&"KIEM",'Daily Report'!$A$7:$A$200,">="&'Cumulative Table'!$AF$7,'Daily Report'!$A$7:$A$200,"<="&'Cumulative Table'!$AG$7) -> 133 | AI8: =SUMIFS('Daily Report'!$H$7:$H$200,'Daily Report'!$AD$7:$AD$200,'Cumulative Table'!$X8&"TAIKIEM",'Daily Report'!$A$7:$A$200,">="&'Cumulative Table'!$AF$7,'Daily Report'!$A$7:$A$200,"<="&'Cumulative Table'!$AG$7) -> 18
D9: WH | E9: M | F9: =SUMIF('Dữ Liệu'!#REF!,'Cumulative Table'!$X9,'Dữ Liệu'!$H$7:$H$134) -> #REF! | G9: =SUMIF('Daily Report'!$AD$7:$AD$263,'Cumulative Table'!$X9&"KIEM",'Daily Report'!$H$7:$H$263) -> 603 | H9: =SUMIF('Daily Report'!$AD$7:$AD$263,'Cumulative Table'!$X9&"TAIKIEM",'Daily Report'!$H$7:$H$263) -> 76 | I9: =SUMIF('Daily Report'!$AE$7:$AE$263,'Cumulative Table'!$X9,'Daily Report'!$I$7:$I$263) -> 603 | J9: =SUMIF('Daily Report'!AE9:AE265,'Cumulative Table'!X9:X203,'Daily Report'!R9:R265) -> 0 | N9: =SUM(K9:M9) -> 0 | O9: =SUMIF('Daily Report'!$AE$7:$AE$263,'Cumulative Table'!$X9,'Daily Report'!$K$7:$K$263) -> 2 | P9: =SUMIF('Daily Report'!$AE$7:$AE$263,'Cumulative Table'!$X9,'Daily Report'!$L$7:$L$263) -> 0 | Q9: =SUMIF('Daily Report'!$AE$7:$AE$263,'Cumulative Table'!$X9,'Daily Report'!$M$7:$M$263) -> 11 | R9: =SUMIF('Daily Report'!$AE$7:$AE$263,'Cumulative Table'!$X9,'Daily Report'!$N$7:$N$263) -> 5 | S9: =SUMIF('Daily Report'!$AE$7:$AE$263,'Cumulative Table'!$X9,'Daily Report'!$O$7:$O$263) -> 42 | T9: =SUMIF('Daily Report'!$AE$7:$AE$263,'Cumulative Table'!$X9,'Daily Report'!$P$7:$P$263) -> 16 | U9: =SUMIF('Daily Report'!$AE$7:$AE$263,'Cumulative Table'!$X9,'Daily Report'!$Q$7:$Q$263) -> 0 | W9: =H9/G9 -> 0.12603648 | X9: =A$7&D9&E9 -> BR9125WHM | Z9: =SUMIFS('Daily Report'!$H$7:$H$263, 'Daily Report'!$AD$7:$AD$263, $X9&"KIEM", 'Daily Report'!$A$7:$A$263, $Y$7) -> 0 | AB9: =SUMIFS('Daily Report'!$H$7:$H$200,'Daily Report'!$AD$7:$AD$200,'Cumulative Table'!$X9&"KIEM",'Daily Report'!$A$7:$A$200,'Cumulative Table'!$AA$7) -> 0 | AD9: =SUMIFS('Daily Report'!$H$7:$H$200,'Daily Report'!$AD$7:$AD$200,'Cumulative Table'!$X9&"KIEM",'Daily Report'!$A$7:$A$200,'Cumulative Table'!$AC$7) -> 184 | AE9: =SUMIFS('Daily Report'!$H$7:$H$200,'Daily Report'!$AD$7:$AD$200,'Cumulative Table'!$X9&"KIEM",'Daily Report'!$A$7:$A$200,">="&'Cumulative Table'!$Y$7,'Daily Report'!$A$7:$A$200,"<="&'Cumulative Table'!$AC$7) -> 184 | AH9: =SUMIFS('Daily Report'!$H$7:$H$200,'Daily Report'!$AD$7:$AD$200,'Cumulative Table'!$X9&"KIEM",'Daily Report'!$A$7:$A$200,">="&'Cumulative Table'!$AF$7,'Daily Report'!$A$7:$A$200,"<="&'Cumulative Table'!$AG$7) -> 184 | AI9: =SUMIFS('Daily Report'!$H$7:$H$200,'Daily Report'!$AD$7:$AD$200,'Cumulative Table'!$X9&"TAIKIEM",'Daily Report'!$A$7:$A$200,">="&'Cumulative Table'!$AF$7,'Daily Report'!$A$7:$A$200,"<="&'Cumulative Table'!$AG$7) -> 24
D10: WH | E10: L | F10: =SUMIF('Dữ Liệu'!#REF!,'Cumulative Table'!$X10,'Dữ Liệu'!$H$7:$H$134) -> #REF! | G10: =SUMIF('Daily Report'!$AD$7:$AD$263,'Cumulative Table'!$X10&"KIEM",'Daily Report'!$H$7:$H$263) -> 188 | H10: =SUMIF('Daily Report'!$AD$7:$AD$263,'Cumulative Table'!$X10&"TAIKIEM",'Daily Report'!$H$7:$H$263) -> 25 | I10: =SUMIF('Daily Report'!$AE$7:$AE$263,'Cumulative Table'!$X10,'Daily Report'!$I$7:$I$263) -> 188 | J10: =SUMIF('Daily Report'!AE10:AE266,'Cumulative Table'!X10:X204,'Daily Report'!R10:R266) -> 0 | N10: =SUM(K10:M10) -> 0 | O10: =SUMIF('Daily Report'!$AE$7:$AE$263,'Cumulative Table'!$X10,'Daily Report'!$K$7:$K$263) -> 1 | P10: =SUMIF('Daily Report'!$AE$7:$AE$263,'Cumulative Table'!$X10,'Daily Report'!$L$7:$L$263) -> 0 | Q10: =SUMIF('Daily Report'!$AE$7:$AE$263,'Cumulative Table'!$X10,'Daily Report'!$M$7:$M$263) -> 3 | R10: =SUMIF('Daily Report'!$AE$7:$AE$263,'Cumulative Table'!$X10,'Daily Report'!$N$7:$N$263) -> 0 | S10: =SUMIF('Daily Report'!$AE$7:$AE$263,'Cumulative Table'!$X10,'Daily Report'!$O$7:$O$263) -> 14 | T10: =SUMIF('Daily Report'!$AE$7:$AE$263,'Cumulative Table'!$X10,'Daily Report'!$P$7:$P$263) -> 7 | U10: =SUMIF('Daily Report'!$AE$7:$AE$263,'Cumulative Table'!$X10,'Daily Report'!$Q$7:$Q$263) -> 0 | W10: =H10/G10 -> 0.13297872 | X10: =A$7&D10&E10 -> BR9125WHL | Z10: =SUMIFS('Daily Report'!$H$7:$H$263, 'Daily Report'!$AD$7:$AD$263, $X10&"KIEM", 'Daily Report'!$A$7:$A$263, $Y$7) -> 188 | AB10: =SUMIFS('Daily Report'!$H$7:$H$200,'Daily Report'!$AD$7:$AD$200,'Cumulative Table'!$X10&"KIEM",'Daily Report'!$A$7:$A$200,'Cumulative Table'!$AA$7) -> 0 | AD10: =SUMIFS('Daily Report'!$H$7:$H$200,'Daily Report'!$AD$7:$AD$200,'Cumulative Table'!$X10&"KIEM",'Daily Report'!$A$7:$A$200,'Cumulative Table'!$AC$7) -> 0 | AE10: =SUMIFS('Daily Report'!$H$7:$H$200,'Daily Report'!$AD$7:$AD$200,'Cumulative Table'!$X10&"KIEM",'Daily Report'!$A$7:$A$200,">="&'Cumulative Table'!$Y$7,'Daily Report'!$A$7:$A$200,"<="&'Cumulative Table'!$AC$7) -> 188 | AH10: =SUMIFS('Daily Report'!$H$7:$H$200,'Daily Report'!$AD$7:$AD$200,'Cumulative Table'!$X10&"KIEM",'Daily Report'!$A$7:$A$200,">="&'Cumulative Table'!$AF$7,'Daily Report'!$A$7:$A$200,"<="&'Cumulative Table'!$AG$7) -> 188 | AI10: =SUMIFS('Daily Report'!$H$7:$H$200,'Daily Report'!$AD$7:$AD$200,'Cumulative Table'!$X10&"TAIKIEM",'Daily Report'!$A$7:$A$200,">="&'Cumulative Table'!$AF$7,'Daily Report'!$A$7:$A$200,"<="&'Cumulative Table'!$AG$7) -> 25
D11: WH | E11: LL | F11: =SUMIF('Dữ Liệu'!#REF!,'Cumulative Table'!$X11,'Dữ Liệu'!$H$7:$H$134) -> #REF! | G11: =SUMIF('Daily Report'!$AD$7:$AD$263,'Cumulative Table'!$X11&"KIEM",'Daily Report'!$H$7:$H$263) -> 128 | H11: =SUMIF('Daily Report'!$AD$7:$AD$263,'Cumulative Table'!$X11&"TAIKIEM",'Daily Report'!$H$7:$H$263) -> 14 | I11: =SUMIF('Daily Report'!$AE$7:$AE$263,'Cumulative Table'!$X11,'Daily Report'!$I$7:$I$263) -> 128 | J11: =SUMIF('Daily Report'!AE11:AE267,'Cumulative Table'!X11:X205,'Daily Report'!R11:R267) -> 0 | N11: =SUM(K11:M11) -> 0 | O11: =SUMIF('Daily Report'!$AE$7:$AE$263,'Cumulative Table'!$X11,'Daily Report'!$K$7:$K$263) -> 0 | P11: =SUMIF('Daily Report'!$AE$7:$AE$263,'Cumulative Table'!$X11,'Daily Report'!$L$7:$L$263) -> 0 | Q11: =SUMIF('Daily Report'!$AE$7:$AE$263,'Cumulative Table'!$X11,'Daily Report'!$M$7:$M$263) -> 3 | R11: =SUMIF('Daily Report'!$AE$7:$AE$263,'Cumulative Table'!$X11,'Daily Report'!$N$7:$N$263) -> 0 | S11: =SUMIF('Daily Report'!$AE$7:$AE$263,'Cumulative Table'!$X11,'Daily Report'!$O$7:$O$263) -> 8 | T11: =SUMIF('Daily Report'!$AE$7:$AE$263,'Cumulative Table'!$X11,'Daily Report'!$P$7:$P$263) -> 3 | U11: =SUMIF('Daily Report'!$AE$7:$AE$263,'Cumulative Table'!$X11,'Daily Report'!$Q$7:$Q$263) -> 0 | W11: =H11/G11 -> 0.109375 | X11: =A$7&D11&E11 -> BR9125WHLL | Z11: =SUMIFS('Daily Report'!$H$7:$H$263, 'Daily Report'!$AD$7:$AD$263, $X11&"KIEM", 'Daily Report'!$A$7:$A$263, $Y$7) -> 104 | AB11: =SUMIFS('Daily Report'!$H$7:$H$200,'Daily Report'!$AD$7:$AD$200,'Cumulative Table'!$X11&"KIEM",'Daily Report'!$A$7:$A$200,'Cumulative Table'!$AA$7) -> 0 | AD11: =SUMIFS('Daily Report'!$H$7:$H$200,'Daily Report'!$AD$7:$AD$200,'Cumulative Table'!$X11&"KIEM",'Daily Report'!$A$7:$A$200,'Cumulative Table'!$AC$7) -> 24 | AE11: =SUMIFS('Daily Report'!$H$7:$H$200,'Daily Report'!$AD$7:$AD$200,'Cumulative Table'!$X11&"KIEM",'Daily Report'!$A$7:$A$200,">="&'Cumulative Table'!$Y$7,'Daily Report'!$A$7:$A$200,"<="&'Cumulative Table'!$AC$7) -> 128 | AH11: =SUMIFS('Daily Report'!$H$7:$H$200,'Daily Report'!$AD$7:$AD$200,'Cumulative Table'!$X11&"KIEM",'Daily Report'!$A$7:$A$200,">="&'Cumulative Table'!$AF$7,'Daily Report'!$A$7:$A$200,"<="&'Cumulative Table'!$AG$7) -> 128 | AI11: =SUMIFS('Daily Report'!$H$7:$H$200,'Daily Report'!$AD$7:$AD$200,'Cumulative Table'!$X11&"TAIKIEM",'Daily Report'!$A$7:$A$200,">="&'Cumulative Table'!$AF$7,'Daily Report'!$A$7:$A$200,"<="&'Cumulative Table'!$AG$7) -> 14
D12: WH | E12: EL | F12: =SUMIF('Dữ Liệu'!#REF!,'Cumulative Table'!$X12,'Dữ Liệu'!$H$7:$H$134) -> #REF! | G12: =SUMIF('Daily Report'!$AD$7:$AD$263,'Cumulative Table'!$X12&"KIEM",'Daily Report'!$H$7:$H$263) -> 23 | H12: =SUMIF('Daily Report'!$AD$7:$AD$263,'Cumulative Table'!$X12&"TAIKIEM",'Daily Report'!$H$7:$H$263) -> 2 | I12: =SUMIF('Daily Report'!$AE$7:$AE$263,'Cumulative Table'!$X12,'Daily Report'!$I$7:$I$263) -> 23 | J12: =SUMIF('Daily Report'!AE12:AE268,'Cumulative Table'!X12:X206,'Daily Report'!R12:R268) -> 0 | N12: =SUM(K12:M12) -> 0 | O12: =SUMIF('Daily Report'!$AE$7:$AE$263,'Cumulative Table'!$X12,'Daily Report'!$K$7:$K$263) -> 0 | P12: =SUMIF('Daily Report'!$AE$7:$AE$263,'Cumulative Table'!$X12,'Daily Report'!$L$7:$L$263) -> 0 | Q12: =SUMIF('Daily Report'!$AE$7:$AE$263,'Cumulative Table'!$X12,'Daily Report'!$M$7:$M$263) -> 0 | R12: =SUMIF('Daily Report'!$AE$7:$AE$263,'Cumulative Table'!$X12,'Daily Report'!$N$7:$N$263) -> 0 | S12: =SUMIF('Daily Report'!$AE$7:$AE$263,'Cumulative Table'!$X12,'Daily Report'!$O$7:$O$263) -> 2 | T12: =SUMIF('Daily Report'!$AE$7:$AE$263,'Cumulative Table'!$X12,'Daily Report'!$P$7:$P$263) -> 0 | U12: =SUMIF('Daily Report'!$AE$7:$AE$263,'Cumulative Table'!$X12,'Daily Report'!$Q$7:$Q$263) -> 0 | W12: =H12/G12 -> 0.086956522 | X12: =A$7&D12&E12 -> BR9125WHEL | Z12: =SUMIFS('Daily Report'!$H$7:$H$263, 'Daily Report'!$AD$7:$AD$263, $X12&"KIEM", 'Daily Report'!$A$7:$A$263, $Y$7) -> 0 | AB12: =SUMIFS('Daily Report'!$H$7:$H$200,'Daily Report'!$AD$7:$AD$200,'Cumulative Table'!$X12&"KIEM",'Daily Report'!$A$7:$A$200,'Cumulative Table'!$AA$7) -> 0 | AD12: =SUMIFS('Daily Report'!$H$7:$H$200,'Daily Report'!$AD$7:$AD$200,'Cumulative Table'!$X12&"KIEM",'Daily Report'!$A$7:$A$200,'Cumulative Table'!$AC$7) -> 23 | AE12: =SUMIFS('Daily Report'!$H$7:$H$200,'Daily Report'!$AD$7:$AD$200,'Cumulative Table'!$X12&"KIEM",'Daily Report'!$A$7:$A$200,">="&'Cumulative Table'!$Y$7,'Daily Report'!$A$7:$A$200,"<="&'Cumulative Table'!$AC$7) -> 23 | AH12: =SUMIFS('Daily Report'!$H$7:$H$200,'Daily Report'!$AD$7:$AD$200,'Cumulative Table'!$X12&"KIEM",'Daily Report'!$A$7:$A$200,">="&'Cumulative Table'!$AF$7,'Daily Report'!$A$7:$A$200,"<="&'Cumulative Table'!$AG$7) -> 23 | AI12: =SUMIFS('Daily Report'!$H$7:$H$200,'Daily Report'!$AD$7:$AD$200,'Cumulative Table'!$X12&"TAIKIEM",'Daily Report'!$A$7:$A$200,">="&'Cumulative Table'!$AF$7,'Daily Report'!$A$7:$A$200,"<="&'Cumulative Table'!$AG$7) -> 2
D13: WH | E13: 4L | F13: =SUMIF('Dữ Liệu'!#REF!,'Cumulative Table'!$X13,'Dữ Liệu'!$H$7:$H$134) -> #REF! | G13: =SUMIF('Daily Report'!$AD$7:$AD$263,'Cumulative Table'!$X13&"KIEM",'Daily Report'!$H$7:$H$263) -> 14 | H13: =SUMIF('Daily Report'!$AD$7:$AD$263,'Cumulative Table'!$X13&"TAIKIEM",'Daily Report'!$H$7:$H$263) -> 1 | I13: =SUMIF('Daily Report'!$AE$7:$AE$263,'Cumulative Table'!$X13,'Daily Report'!$I$7:$I$263) -> 14 | J13: =SUMIF('Daily Report'!AE13:AE269,'Cumulative Table'!X13:X207,'Daily Report'!R13:R269) -> 0 | N13: =SUM(K13:M13) -> 0 | O13: =SUMIF('Daily Report'!$AE$7:$AE$263,'Cumulative Table'!$X13,'Daily Report'!$K$7:$K$263) -> 0 | P13: =SUMIF('Daily Report'!$AE$7:$AE$263,'Cumulative Table'!$X13,'Daily Report'!$L$7:$L$263) -> 0 | Q13: =SUMIF('Daily Report'!$AE$7:$AE$263,'Cumulative Table'!$X13,'Daily Report'!$M$7:$M$263) -> 1 | R13: =SUMIF('Daily Report'!$AE$7:$AE$263,'Cumulative Table'!$X13,'Daily Report'!$N$7:$N$263) -> 0 | S13: =SUMIF('Daily Report'!$AE$7:$AE$263,'Cumulative Table'!$X13,'Daily Report'!$O$7:$O$263) -> 0 | T13: =SUMIF('Daily Report'!$AE$7:$AE$263,'Cumulative Table'!$X13,'Daily Report'!$P$7:$P$263) -> 0 | U13: =SUMIF('Daily Report'!$AE$7:$AE$263,'Cumulative Table'!$X13,'Daily Report'!$Q$7:$Q$263) -> 0 | W13: =H13/G13 -> 0.071428571 | X13: =A$7&D13&E13 -> BR9125WH4L | Z13: =SUMIFS('Daily Report'!$H$7:$H$263, 'Daily Report'!$AD$7:$AD$263, $X13&"KIEM", 'Daily Report'!$A$7:$A$263, $Y$7) -> 0 | AB13: =SUMIFS('Daily Report'!$H$7:$H$200,'Daily Report'!$AD$7:$AD$200,'Cumulative Table'!$X13&"KIEM",'Daily Report'!$A$7:$A$200,'Cumulative Table'!$AA$7) -> 0 | AD13: =SUMIFS('Daily Report'!$H$7:$H$200,'Daily Report'!$AD$7:$AD$200,'Cumulative Table'!$X13&"KIEM",'Daily Report'!$A$7:$A$200,'Cumulative Table'!$AC$7) -> 14 | AE13: =SUMIFS('Daily Report'!$H$7:$H$200,'Daily Report'!$AD$7:$AD$200,'Cumulative Table'!$X13&"KIEM",'Daily Report'!$A$7:$A$200,">="&'Cumulative Table'!$Y$7,'Daily Report'!$A$7:$A$200,"<="&'Cumulative Table'!$AC$7) -> 14 | AH13: =SUMIFS('Daily Report'!$H$7:$H$200,'Daily Report'!$AD$7:$AD$200,'Cumulative Table'!$X13&"KIEM",'Daily Report'!$A$7:$A$200,">="&'Cumulative Table'!$AF$7,'Daily Report'!$A$7:$A$200,"<="&'Cumulative Table'!$AG$7) -> 14 | AI13: =SUMIFS('Daily Report'!$H$7:$H$200,'Daily Report'!$AD$7:$AD$200,'Cumulative Table'!$X13&"TAIKIEM",'Daily Report'!$A$7:$A$200,">="&'Cumulative Table'!$AF$7,'Daily Report'!$A$7:$A$200,"<="&'Cumulative Table'!$AG$7) -> 1
D14: WH | E14: 5L | F14: =SUMIF('Dữ Liệu'!#REF!,'Cumulative Table'!$X14,'Dữ Liệu'!$H$7:$H$134) -> #REF! | G14: =SUMIF('Daily Report'!$AD$7:$AD$263,'Cumulative Table'!$X14&"KIEM",'Daily Report'!$H$7:$H$263) -> 13 | H14: =SUMIF('Daily Report'!$AD$7:$AD$263,'Cumulative Table'!$X14&"TAIKIEM",'Daily Report'!$H$7:$H$263) -> 1 | I14: =SUMIF('Daily Report'!$AE$7:$AE$263,'Cumulative Table'!$X14,'Daily Report'!$I$7:$I$263) -> 13 | J14: =SUMIF('Daily Report'!AE13:AE269,'Cumulative Table'!X14:X207,'Daily Report'!R13:R269) -> 0 | N14: =SUM(K14:M14) -> 0 | O14: =SUMIF('Daily Report'!$AE$7:$AE$263,'Cumulative Table'!$X14,'Daily Report'!$K$7:$K$263) -> 0 | P14: =SUMIF('Daily Report'!$AE$7:$AE$263,'Cumulative Table'!$X14,'Daily Report'!$L$7:$L$263) -> 0 | Q14: =SUMIF('Daily Report'!$AE$7:$AE$263,'Cumulative Table'!$X14,'Daily Report'!$M$7:$M$263) -> 0 | R14: =SUMIF('Daily Report'!$AE$7:$AE$263,'Cumulative Table'!$X14,'Daily Report'!$N$7:$N$263) -> 0 | S14: =SUMIF('Daily Report'!$AE$7:$AE$263,'Cumulative Table'!$X14,'Daily Report'!$O$7:$O$263) -> 1 | T14: =SUMIF('Daily Report'!$AE$7:$AE$263,'Cumulative Table'!$X14,'Daily Report'!$P$7:$P$263) -> 0 | U14: =SUMIF('Daily Report'!$AE$7:$AE$263,'Cumulative Table'!$X14,'Daily Report'!$Q$7:$Q$263) -> 0 | W14: =H14/G14 -> 0.076923077 | X14: =A$7&D14&E14 -> BR9125WH5L | Z14: =SUMIFS('Daily Report'!$H$7:$H$263, 'Daily Report'!$AD$7:$AD$263, $X14&"KIEM", 'Daily Report'!$A$7:$A$263, $Y$7) -> 0 | AB14: =SUMIFS('Daily Report'!$H$7:$H$200,'Daily Report'!$AD$7:$AD$200,'Cumulative Table'!$X14&"KIEM",'Daily Report'!$A$7:$A$200,'Cumulative Table'!$AA$7) -> 0 | AD14: =SUMIFS('Daily Report'!$H$7:$H$200,'Daily Report'!$AD$7:$AD$200,'Cumulative Table'!$X14&"KIEM",'Daily Report'!$A$7:$A$200,'Cumulative Table'!$AC$7) -> 13 | AE14: =SUMIFS('Daily Report'!$H$7:$H$200,'Daily Report'!$AD$7:$AD$200,'Cumulative Table'!$X14&"KIEM",'Daily Report'!$A$7:$A$200,">="&'Cumulative Table'!$Y$7,'Daily Report'!$A$7:$A$200,"<="&'Cumulative Table'!$AC$7) -> 13 | AH14: =SUMIFS('Daily Report'!$H$7:$H$200,'Daily Report'!$AD$7:$AD$200,'Cumulative Table'!$X14&"KIEM",'Daily Report'!$A$7:$A$200,">="&'Cumulative Table'!$AF$7,'Daily Report'!$A$7:$A$200,"<="&'Cumulative Table'!$AG$7) -> 13 | AI14: =SUMIFS('Daily Report'!$H$7:$H$200,'Daily Report'!$AD$7:$AD$200,'Cumulative Table'!$X14&"TAIKIEM",'Daily Report'!$A$7:$A$200,">="&'Cumulative Table'!$AF$7,'Daily Report'!$A$7:$A$200,"<="&'Cumulative Table'!$AG$7) -> 1
D15: WH | E15: 6L | F15: =SUMIF('Dữ Liệu'!#REF!,'Cumulative Table'!$X15,'Dữ Liệu'!$H$7:$H$134) -> #REF! | G15: =SUMIF('Daily Report'!$AD$7:$AD$263,'Cumulative Table'!$X15&"KIEM",'Daily Report'!$H$7:$H$263) -> 0 | H15: =SUMIF('Daily Report'!$AD$7:$AD$263,'Cumulative Table'!$X15&"TAIKIEM",'Daily Report'!$H$7:$H$263) -> 0 | I15: =SUMIF('Daily Report'!$AE$7:$AE$263,'Cumulative Table'!$X15,'Daily Report'!$I$7:$I$263) -> 0 | J15: =SUMIF('Daily Report'!AE14:AE270,'Cumulative Table'!X15:X208,'Daily Report'!R14:R270) -> 0 | N15: =SUM(K15:M15) -> 0 | O15: =SUMIF('Daily Report'!$AE$7:$AE$263,'Cumulative Table'!$X15,'Daily Report'!$K$7:$K$263) -> 0 | P15: =SUMIF('Daily Report'!$AE$7:$AE$263,'Cumulative Table'!$X15,'Daily Report'!$L$7:$L$263) -> 0 | Q15: =SUMIF('Daily Report'!$AE$7:$AE$263,'Cumulative Table'!$X15,'Daily Report'!$M$7:$M$263) -> 0 | R15: =SUMIF('Daily Report'!$AE$7:$AE$263,'Cumulative Table'!$X15,'Daily Report'!$N$7:$N$263) -> 0 | S15: =SUMIF('Daily Report'!$AE$7:$AE$263,'Cumulative Table'!$X15,'Daily Report'!$O$7:$O$263) -> 0 | T15: =SUMIF('Daily Report'!$AE$7:$AE$263,'Cumulative Table'!$X15,'Daily Report'!$P$7:$P$263) -> 0 | U15: =SUMIF('Daily Report'!$AE$7:$AE$263,'Cumulative Table'!$X15,'Daily Report'!$Q$7:$Q$263) -> 0 | W15: =H15/G15 -> #DIV/0! | X15: =A$7&D15&E15 -> BR9125WH6L | Z15: =SUMIFS('Daily Report'!$H$7:$H$263, 'Daily Report'!$AD$7:$AD$263, $X15&"KIEM", 'Daily Report'!$A$7:$A$263, $Y$7) -> 0 | AB15: =SUMIFS('Daily Report'!$H$7:$H$200,'Daily Report'!$AD$7:$AD$200,'Cumulative Table'!$X15&"KIEM",'Daily Report'!$A$7:$A$200,'Cumulative Table'!$AA$7) -> 0 | AD15: =SUMIFS('Daily Report'!$H$7:$H$200,'Daily Report'!$AD$7:$AD$200,'Cumulative Table'!$X15&"KIEM",'Daily Report'!$A$7:$A$200,'Cumulative Table'!$AC$7) -> 0 | AE15: =SUMIFS('Daily Report'!$H$7:$H$200,'Daily Report'!$AD$7:$AD$200,'Cumulative Table'!$X15&"KIEM",'Daily Report'!$A$7:$A$200,">="&'Cumulative Table'!$Y$7,'Daily Report'!$A$7:$A$200,"<="&'Cumulative Table'!$AC$7) -> 0 | AH15: =SUMIFS('Daily Report'!$H$7:$H$200,'Daily Report'!$AD$7:$AD$200,'Cumulative Table'!$X15&"KIEM",'Daily Report'!$A$7:$A$200,">="&'Cumulative Table'!$AF$7,'Daily Report'!$A$7:$A$200,"<="&'Cumulative Table'!$AG$7) -> 0 | AI15: =SUMIFS('Daily Report'!$H$7:$H$200,'Daily Report'!$AD$7:$AD$200,'Cumulative Table'!$X15&"TAIKIEM",'Daily Report'!$A$7:$A$200,">="&'Cumulative Table'!$AF$7,'Daily Report'!$A$7:$A$200,"<="&'Cumulative Table'!$AG$7) -> 0
A16: 合計数 Tổng | F16: =SUM(F7:F15) -> #REF! | G16: =SUM(G7:G15) -> 1102 | H16: =SUM(H7:H15) -> 137 | I16: =SUM(I7:I15) -> 1102 | J16: =SUM(J7:J15) -> 0 | K16: =SUM(K7:K15) -> 0 | L16: =SUM(L7:L15) -> 0 | M16: =SUM(M7:M15) -> 0 | ... P16: =SUM(P7:P15) -> 0 | Q16: =SUMIF('Daily Report'!$AE$7:$AE$263,'Cumulative Table'!$X16,'Daily Report'!$M$7:$M$263) -> 0 | R16: =SUM(R7:R15) -> 5 | S16: =SUM(S7:S15) -> 79 | T16: =SUM(T7:T15) -> 30 | U16: =SUM(U7:U15) -> 0 | V16: =SUM(V7:V15) -> 0 | W16: =H16/G16 -> 0.12431942
A17: 不良項目 | C17: 寸法不良： | D17: 袖丈-1.5CM, 着丈-4CM, 袖丈-2CM | H17: 付属・装飾不良： | I17: テープ無し, 品質ネームサイズ違い, プリント不良, 品質ネーム汚れ, サイズネーム曲がり
C18: 外観・仕上げ不良： | D18: 袖非対称, アタリ, 衿バランス不良, ダブリ, しわ, 捻じれ | H18: 生地不良： | I18: スリップ, 生折れ, キズ
C19: 汚れ不良： | D19: 油汚れ | H19: 縫製不良： | I19: パンク, 縫い止め逆付け, 糸切れ, 縫い摘み, 縫いつまみ, 縫い止め無し
C20: その他：
A21: CHI TIẾT LỖI | C21: THÔNG SỐ： | D21: DAI TAY -1.5CM, DAI AO -4CM, DAI TAY -2CM | H21: PHỤ LIỆU: | I21: THIEU TEP, NHAN GIAT LON SIZE, IN DUN, NHAN GIAT DO MUC, IN NHAN SIZE XEO
C22: HÌNH DÁNG: | D22: TAY SOLE, CAN, CO MEO, DUN, NHAN, RAP BO CO VAN | H22: VẢI: | I22: BE VAI, SOC VAI, XUOC
C23: DƠ: | D23: DAU | H23: CÁCH MAY: | I23: XI, CHOT NGUOC, DUT CHI , XEP LY, NHIU, THIEU CHOT
X24: =A24&D24&E24
A25: 品番 | B25: ブランド | C25: 品目 | D25: カラー | E25: サイズ | F25: ロット数 | G25: 検品数(初回検品のみ) | H25: 再検品数量(2回目以降の検査も含む) | I25: 良品数(初回・それ以降の検査分含む) | J25: 検針良品数(初回・それ以降の検査分含む) | K25: 出荷済み数量 | O25: Thông số | P25: Phụ liệu | Q25: Ngoại quan | R25: Vải | S25: Dơ | T25: Lổi may | U25: Khác | V25: Kiểm Kim | W25: Tỉ lệ lỗi
A26: Style No | B26: Brand | C26: Item | D26: Color | E26: Size | F26: Order Qty | G26: Inspection Qty | H26: Re-inspection Qty | I26: A-Grade Qty | J26: A-Grade Qty | K26: Shipment Qty | O26: Measurment | P26: Material | Q26: Appearance | R26: Fabric | S26: Dirt | T26: Sewing | U26: Other | V26: Needle Inspection | W26: rate | Y26: KIỂM | AF26: TỔNG NGÀY KIỂM
A27: Mã hàng | B27: Thương hiệu | C27: Tên hàng | D27: Màu | E27: Size | F27: Số lượng đơn hàng | G27: SL kiểm hàng | H27: SL tái kiểm | I27: SL Hàng đạt | J27: SL Hàng đạt Kiểm kim | K27: SL xuất 1 | L27: SL xuất 2 | M27: SL xuất 3 | N27: TỔNG XUẤT | O27: 採寸不良 | P27: 付属不良 | Q27: 外観不良 | R27: 生地不良 | S27: 汚れ不良 | T27: 縫製不良 | U27: その他 | V27: 検針 | W27: 不良率 | Y27: NGÀY 2026/03/05 | AA27: NGÀY 2026/03/09 | AC27: NGÀY 2026/03/10 | AE27: 2026/03/05 - 03/10 | AF27: NGÀY BẮT ĐẦU | AG27: NGÀY KẾT THÚC | AH27: TỔNG SỐ HÀNG KIỂM | AI27: TỔNG SỐ HÀNG TÁI
A28: BR9125 | B28: =VLOOKUP($A$7,'Daily Report'!$C$7:$E$263,2,FALSE) -> GUA | C28: =VLOOKUP($A$7,'Daily Report'!$C$7:$E$263,3,FALSE) -> SHIRT | D28: WH | E28: SS | F28: =SUMIF('Dữ Liệu'!#REF!,'Cumulative Table'!$X7,'Dữ Liệu'!H7:H134) -> #REF! | G28: =SUMIF('Daily Report'!$AD$7:$AD$263,'Cumulative Table'!$X$7:$X$201&"KIEM",'Daily Report'!$H$7:$H$199) -> 0 | H28: =SUMIF('Daily Report'!$AD$7:$AD$263,'Cumulative Table'!$X$7:$X$201&"TAIKIEM",'Daily Report'!$H$7:$H$263) -> 0 | I28: =SUMIF('Daily Report'!$AE$7:$AE$263,'Cumulative Table'!$X$7:$X$201,'Daily Report'!$I$7:$I$263) -> 0 | J28: =SUMIF('Daily Report'!AE27:AE283,'Cumulative Table'!X28:X221,'Daily Report'!R27:R283) -> 0 | N28: =SUM(K28:M28) -> 0 | O28: =SUMIF('Daily Report'!$AE$7:$AE$199,'Cumulative Table'!$X$7:$X$201,'Daily Report'!$K$7:$K$199) -> 0 | P28: =SUMIF('Daily Report'!$AE$7:$AE$263,'Cumulative Table'!X$7:$X$201,'Daily Report'!$L$7:$L$263) -> 0 | Q28: =SUMIF('Daily Report'!$AE$7:$AE$263,'Cumulative Table'!$X$7:$X$201,'Daily Report'!$M$7:$M$263) -> 0 | R28: =SUMIF('Daily Report'!$AE$7:$AE$263,'Cumulative Table'!$X$7:$X$201,'Daily Report'!$N$7:$N$263) -> 0 | S28: =SUMIF('Daily Report'!$AE$7:$AE$263,'Cumulative Table'!$X$7:$X$201,'Daily Report'!$O$7:$O$263) -> 0 | T28: =SUMIF('Daily Report'!$AE$7:$AE$263,'Cumulative Table'!$X$8:$X$201,'Daily Report'!$P$7:$P$263) -> 0 | U28: =SUMIF('Daily Report'!$AE$7:$AE$263,'Cumulative Table'!$X$7:$X$201,'Daily Report'!$Q$7:$Q$263) -> 0 | W28: =H28/G28 -> #DIV/0! | X28: =$A$28&D28&E28 -> BR9125WHSS | Y28: 46095 | Z28: =SUMIFS('Daily Report'!$H$7:$H$263, 'Daily Report'!$AD$7:$AD$263, $X28&"KIEM", 'Daily Report'!$A$7:$A$263, $Y$28) -> 0 | AA28: 46096 | AB28: =SUMIFS('Daily Report'!$H$7:$H$200,'Daily Report'!$AD$7:$AD$200,'Cumulative Table'!$X28&"KIEM",'Daily Report'!$A$7:$A$200,'Cumulative Table'!$AA$28) -> 0 | AC28: 46097 | AD28: =SUMIFS('Daily Report'!$H$7:$H$200,'Daily Report'!$AD$7:$AD$200,'Cumulative Table'!$X28&"KIEM",'Daily Report'!$A$7:$A$200,'Cumulative Table'!$AC$28) -> 0 | AE28: =SUMIFS('Daily Report'!$H$7:$H$200,'Daily Report'!$AD$7:$AD$200,'Cumulative Table'!$X28&"KIEM",'Daily Report'!$A$7:$A$200,">="&'Cumulative Table'!$Y$28,'Daily Report'!$A$7:$A$200,"<="&'Cumulative Table'!$AC$28) -> 0 | AF28: 46096 | AG28: 46097 | AH28: =SUMIFS('Daily Report'!$H$7:$H$200,'Daily Report'!$AD$7:$AD$200,'Cumulative Table'!$X28&"KIEM",'Daily Report'!$A$7:$A$200,">="&'Cumulative Table'!$AF$28,'Daily Report'!$A$7:$A$200,"<="&'Cumulative Table'!$AG$28) -> 0 | AI28: =SUMIFS('Daily Report'!$H$7:$H$200,'Daily Report'!$AD$7:$AD$200,'Cumulative Table'!$X28&"TAIKIEM",'Daily Report'!$A$7:$A$200,">="&'Cumulative Table'!$AF$28,'Daily Report'!$A$7:$A$200,"<="&'Cumulative Table'!$AG$28) -> 0
D29: WH | E29: S | F29: =SUMIF('Dữ Liệu'!#REF!,'Cumulative Table'!$X8,'Dữ Liệu'!H8:H135) -> #REF! | G29: =SUMIF('Daily Report'!$AD$7:$AD$263,'Cumulative Table'!$X$7:$X$201&"KIEM",'Daily Report'!$H$7:$H$199) -> 133 | H29: =SUMIF('Daily Report'!$AD$7:$AD$263,'Cumulative Table'!$X$7:$X$201&"TAIKIEM",'Daily Report'!$H$7:$H$263) -> 18 | I29: =SUMIF('Daily Report'!$AE$7:$AE$263,'Cumulative Table'!$X$7:$X$201,'Daily Report'!$I$7:$I$263) -> 133 | J29: =SUMIF('Daily Report'!AE28:AE284,'Cumulative Table'!X29:X222,'Daily Report'!R28:R284) -> 0 | N29: =SUM(K29:M29) -> 0 | O29: =SUMIF('Daily Report'!$AE$7:$AE$199,'Cumulative Table'!$X$7:$X$201,'Daily Report'!$K$7:$K$199) -> 0 | P29: =SUMIF('Daily Report'!$AE$7:$AE$263,'Cumulative Table'!X$7:$X$201,'Daily Report'!$L$7:$L$263) -> 0 | Q29: =SUMIF('Daily Report'!$AE$7:$AE$263,'Cumulative Table'!$X$7:$X$201,'Daily Report'!$M$7:$M$263) -> 2 | R29: =SUMIF('Daily Report'!$AE$7:$AE$263,'Cumulative Table'!$X$7:$X$201,'Daily Report'!$N$7:$N$263) -> 0 | S29: =SUMIF('Daily Report'!$AE$7:$AE$263,'Cumulative Table'!$X$7:$X$201,'Daily Report'!$O$7:$O$263) -> 12 | T29: =SUMIF('Daily Report'!$AE$7:$AE$263,'Cumulative Table'!$X$8:$X$201,'Daily Report'!$P$7:$P$263) -> 4 | U29: =SUMIF('Daily Report'!$AE$7:$AE$263,'Cumulative Table'!$X$7:$X$201,'Daily Report'!$Q$7:$Q$263) -> 0 | W29: =H29/G29 -> 0.13533835 | X29: =$A$28&D29&E29 -> BR9125WHS | Z29: =SUMIFS('Daily Report'!$H$7:$H$263, 'Daily Report'!$AD$7:$AD$263, $X29&"KIEM", 'Daily Report'!$A$7:$A$263, $Y$28) -> 0 | AB29: =SUMIFS('Daily Report'!$H$7:$H$200,'Daily Report'!$AD$7:$AD$200,'Cumulative Table'!$X29&"KIEM",'Daily Report'!$A$7:$A$200,'Cumulative Table'!$AA$28) -> 0 | AD29: =SUMIFS('Daily Report'!$H$7:$H$200,'Daily Report'!$AD$7:$AD$200,'Cumulative Table'!$X29&"KIEM",'Daily Report'!$A$7:$A$200,'Cumulative Table'!$AC$28) -> 133 | AE29: =SUMIFS('Daily Report'!$H$7:$H$200,'Daily Report'!$AD$7:$AD$200,'Cumulative Table'!$X29&"KIEM",'Daily Report'!$A$7:$A$200,">="&'Cumulative Table'!$Y$28,'Daily Report'!$A$7:$A$200,"<="&'Cumulative Table'!$AC$28) -> 133 | AH29: =SUMIFS('Daily Report'!$H$7:$H$200,'Daily Report'!$AD$7:$AD$200,'Cumulative Table'!$X29&"KIEM",'Daily Report'!$A$7:$A$200,">="&'Cumulative Table'!$AF$28,'Daily Report'!$A$7:$A$200,"<="&'Cumulative Table'!$AG$28) -> 133 | AI29: =SUMIFS('Daily Report'!$H$7:$H$200,'Daily Report'!$AD$7:$AD$200,'Cumulative Table'!$X29&"TAIKIEM",'Daily Report'!$A$7:$A$200,">="&'Cumulative Table'!$AF$28,'Daily Report'!$A$7:$A$200,"<="&'Cumulative Table'!$AG$28) -> 18
D30: WH | E30: M | F30: =SUMIF('Dữ Liệu'!#REF!,'Cumulative Table'!$X9,'Dữ Liệu'!H8:H136) -> #REF! | G30: =SUMIF('Daily Report'!$AD$7:$AD$263,'Cumulative Table'!$X$7:$X$201&"KIEM",'Daily Report'!$H$7:$H$199) -> 603 | H30: =SUMIF('Daily Report'!$AD$7:$AD$263,'Cumulative Table'!$X$7:$X$201&"TAIKIEM",'Daily Report'!$H$7:$H$263) -> 76 | I30: =SUMIF('Daily Report'!$AE$7:$AE$263,'Cumulative Table'!$X$7:$X$201,'Daily Report'!$I$7:$I$263) -> 603 | J30: =SUMIF('Daily Report'!AE29:AE285,'Cumulative Table'!X30:X223,'Daily Report'!R29:R285) -> 0 | N30: =SUM(K30:M30) -> 0 | O30: =SUMIF('Daily Report'!$AE$7:$AE$199,'Cumulative Table'!$X$7:$X$201,'Daily Report'!$K$7:$K$199) -> 2 | P30: =SUMIF('Daily Report'!$AE$7:$AE$263,'Cumulative Table'!X$7:$X$201,'Daily Report'!$L$7:$L$263) -> 0 | Q30: =SUMIF('Daily Report'!$AE$7:$AE$263,'Cumulative Table'!$X$7:$X$201,'Daily Report'!$M$7:$M$263) -> 11 | R30: =SUMIF('Daily Report'!$AE$7:$AE$263,'Cumulative Table'!$X$7:$X$201,'Daily Report'!$N$7:$N$263) -> 5 | S30: =SUMIF('Daily Report'!$AE$7:$AE$263,'Cumulative Table'!$X$7:$X$201,'Daily Report'!$O$7:$O$263) -> 42 | T30: =SUMIF('Daily Report'!$AE$7:$AE$263,'Cumulative Table'!$X$8:$X$201,'Daily Report'!$P$7:$P$263) -> 16 | U30: =SUMIF('Daily Report'!$AE$7:$AE$263,'Cumulative Table'!$X$7:$X$201,'Daily Report'!$Q$7:$Q$263) -> 0 | W30: =H30/G30 -> 0.12603648 | X30: =$A$28&D30&E30 -> BR9125WHM | Z30: =SUMIFS('Daily Report'!$H$7:$H$263, 'Daily Report'!$AD$7:$AD$263, $X30&"KIEM", 'Daily Report'!$A$7:$A$263, $Y$28) -> 0 | AB30: =SUMIFS('Daily Report'!$H$7:$H$200,'Daily Report'!$AD$7:$AD$200,'Cumulative Table'!$X30&"KIEM",'Daily Report'!$A$7:$A$200,'Cumulative Table'!$AA$28) -> 0 | AD30: =SUMIFS('Daily Report'!$H$7:$H$200,'Daily Report'!$AD$7:$AD$200,'Cumulative Table'!$X30&"KIEM",'Daily Report'!$A$7:$A$200,'Cumulative Table'!$AC$28) -> 184 | AE30: =SUMIFS('Daily Report'!$H$7:$H$200,'Daily Report'!$AD$7:$AD$200,'Cumulative Table'!$X30&"KIEM",'Daily Report'!$A$7:$A$200,">="&'Cumulative Table'!$Y$28,'Daily Report'!$A$7:$A$200,"<="&'Cumulative Table'!$AC$28) -> 184 | AH30: =SUMIFS('Daily Report'!$H$7:$H$200,'Daily Report'!$AD$7:$AD$200,'Cumulative Table'!$X30&"KIEM",'Daily Report'!$A$7:$A$200,">="&'Cumulative Table'!$AF$28,'Daily Report'!$A$7:$A$200,"<="&'Cumulative Table'!$AG$28) -> 184 | AI30: =SUMIFS('Daily Report'!$H$7:$H$200,'Daily Report'!$AD$7:$AD$200,'Cumulative Table'!$X30&"TAIKIEM",'Daily Report'!$A$7:$A$200,">="&'Cumulative Table'!$AF$28,'Daily Report'!$A$7:$A$200,"<="&'Cumulative Table'!$AG$28) -> 24
D31: WH | E31: L | F31: =SUMIF('Dữ Liệu'!#REF!,'Cumulative Table'!$X10,'Dữ Liệu'!H8:H137) -> #REF! | G31: =SUMIF('Daily Report'!$AD$7:$AD$263,'Cumulative Table'!$X$7:$X$201&"KIEM",'Daily Report'!$H$7:$H$199) -> 188 | H31: =SUMIF('Daily Report'!$AD$7:$AD$263,'Cumulative Table'!$X$7:$X$201&"TAIKIEM",'Daily Report'!$H$7:$H$263) -> 25 | I31: =SUMIF('Daily Report'!$AE$7:$AE$263,'Cumulative Table'!$X$7:$X$201,'Daily Report'!$I$7:$I$263) -> 188 | J31: =SUMIF('Daily Report'!AE30:AE286,'Cumulative Table'!X31:X224,'Daily Report'!R30:R286) -> 0 | N31: =SUM(K31:M31) -> 0 | O31: =SUMIF('Daily Report'!$AE$7:$AE$199,'Cumulative Table'!$X$7:$X$201,'Daily Report'!$K$7:$K$199) -> 1 | P31: =SUMIF('Daily Report'!$AE$7:$AE$263,'Cumulative Table'!X$7:$X$201,'Daily Report'!$L$7:$L$263) -> 0 | Q31: =SUMIF('Daily Report'!$AE$7:$AE$263,'Cumulative Table'!$X$7:$X$201,'Daily Report'!$M$7:$M$263) -> 3 | R31: =SUMIF('Daily Report'!$AE$7:$AE$263,'Cumulative Table'!$X$7:$X$201,'Daily Report'!$N$7:$N$263) -> 0 | S31: =SUMIF('Daily Report'!$AE$7:$AE$263,'Cumulative Table'!$X$7:$X$201,'Daily Report'!$O$7:$O$263) -> 14 | T31: =SUMIF('Daily Report'!$AE$7:$AE$263,'Cumulative Table'!$X$8:$X$201,'Daily Report'!$P$7:$P$263) -> 7 | U31: =SUMIF('Daily Report'!$AE$7:$AE$263,'Cumulative Table'!$X$7:$X$201,'Daily Report'!$Q$7:$Q$263) -> 0 | W31: =H31/G31 -> 0.13297872 | X31: =$A$28&D31&E31 -> BR9125WHL | Z31: =SUMIFS('Daily Report'!$H$7:$H$263, 'Daily Report'!$AD$7:$AD$263, $X31&"KIEM", 'Daily Report'!$A$7:$A$263, $Y$28) -> 188 | AB31: =SUMIFS('Daily Report'!$H$7:$H$200,'Daily Report'!$AD$7:$AD$200,'Cumulative Table'!$X31&"KIEM",'Daily Report'!$A$7:$A$200,'Cumulative Table'!$AA$28) -> 0 | AD31: =SUMIFS('Daily Report'!$H$7:$H$200,'Daily Report'!$AD$7:$AD$200,'Cumulative Table'!$X31&"KIEM",'Daily Report'!$A$7:$A$200,'Cumulative Table'!$AC$28) -> 0 | AE31: =SUMIFS('Daily Report'!$H$7:$H$200,'Daily Report'!$AD$7:$AD$200,'Cumulative Table'!$X31&"KIEM",'Daily Report'!$A$7:$A$200,">="&'Cumulative Table'!$Y$28,'Daily Report'!$A$7:$A$200,"<="&'Cumulative Table'!$AC$28) -> 188 | AH31: =SUMIFS('Daily Report'!$H$7:$H$200,'Daily Report'!$AD$7:$AD$200,'Cumulative Table'!$X31&"KIEM",'Daily Report'!$A$7:$A$200,">="&'Cumulative Table'!$AF$28,'Daily Report'!$A$7:$A$200,"<="&'Cumulative Table'!$AG$28) -> 0 | AI31: =SUMIFS('Daily Report'!$H$7:$H$200,'Daily Report'!$AD$7:$AD$200,'Cumulative Table'!$X31&"TAIKIEM",'Daily Report'!$A$7:$A$200,">="&'Cumulative Table'!$AF$28,'Daily Report'!$A$7:$A$200,"<="&'Cumulative Table'!$AG$28) -> 0
D32: WH | E32: LL | F32: =SUMIF('Dữ Liệu'!#REF!,'Cumulative Table'!$X11,'Dữ Liệu'!H8:H138) -> #REF! | G32: =SUMIF('Daily Report'!$AD$7:$AD$263,'Cumulative Table'!$X$7:$X$201&"KIEM",'Daily Report'!$H$7:$H$199) -> 128 | H32: =SUMIF('Daily Report'!$AD$7:$AD$263,'Cumulative Table'!$X$7:$X$201&"TAIKIEM",'Daily Report'!$H$7:$H$263) -> 14 | I32: =SUMIF('Daily Report'!$AE$7:$AE$263,'Cumulative Table'!$X$7:$X$201,'Daily Report'!$I$7:$I$263) -> 128 | J32: =SUMIF('Daily Report'!AE31:AE287,'Cumulative Table'!X32:X225,'Daily Report'!R31:R287) -> 0 | N32: =SUM(K32:M32) -> 0 | O32: =SUMIF('Daily Report'!$AE$7:$AE$199,'Cumulative Table'!$X$7:$X$201,'Daily Report'!$K$7:$K$199) -> 0 | P32: =SUMIF('Daily Report'!$AE$7:$AE$263,'Cumulative Table'!X$7:$X$201,'Daily Report'!$L$7:$L$263) -> 0 | Q32: =SUMIF('Daily Report'!$AE$7:$AE$263,'Cumulative Table'!$X$7:$X$201,'Daily Report'!$M$7:$M$263) -> 3 | R32: =SUMIF('Daily Report'!$AE$7:$AE$263,'Cumulative Table'!$X$7:$X$201,'Daily Report'!$N$7:$N$263) -> 0 | S32: =SUMIF('Daily Report'!$AE$7:$AE$263,'Cumulative Table'!$X$7:$X$201,'Daily Report'!$O$7:$O$263) -> 8 | T32: =SUMIF('Daily Report'!$AE$7:$AE$263,'Cumulative Table'!$X$8:$X$201,'Daily Report'!$P$7:$P$263) -> 3 | U32: =SUMIF('Daily Report'!$AE$7:$AE$263,'Cumulative Table'!$X$7:$X$201,'Daily Report'!$Q$7:$Q$263) -> 0 | W32: =H32/G32 -> 0.109375 | X32: =$A$28&D32&E32 -> BR9125WHLL | Z32: =SUMIFS('Daily Report'!$H$7:$H$263, 'Daily Report'!$AD$7:$AD$263, $X32&"KIEM", 'Daily Report'!$A$7:$A$263, $Y$28) -> 104 | AB32: =SUMIFS('Daily Report'!$H$7:$H$200,'Daily Report'!$AD$7:$AD$200,'Cumulative Table'!$X32&"KIEM",'Daily Report'!$A$7:$A$200,'Cumulative Table'!$AA$28) -> 0 | AD32: =SUMIFS('Daily Report'!$H$7:$H$200,'Daily Report'!$AD$7:$AD$200,'Cumulative Table'!$X32&"KIEM",'Daily Report'!$A$7:$A$200,'Cumulative Table'!$AC$28) -> 24 | AE32: =SUMIFS('Daily Report'!$H$7:$H$200,'Daily Report'!$AD$7:$AD$200,'Cumulative Table'!$X32&"KIEM",'Daily Report'!$A$7:$A$200,">="&'Cumulative Table'!$Y$28,'Daily Report'!$A$7:$A$200,"<="&'Cumulative Table'!$AC$28) -> 128 | AH32: =SUMIFS('Daily Report'!$H$7:$H$200,'Daily Report'!$AD$7:$AD$200,'Cumulative Table'!$X32&"KIEM",'Daily Report'!$A$7:$A$200,">="&'Cumulative Table'!$AF$28,'Daily Report'!$A$7:$A$200,"<="&'Cumulative Table'!$AG$28) -> 24 | AI32: =SUMIFS('Daily Report'!$H$7:$H$200,'Daily Report'!$AD$7:$AD$200,'Cumulative Table'!$X32&"TAIKIEM",'Daily Report'!$A$7:$A$200,">="&'Cumulative Table'!$AF$28,'Daily Report'!$A$7:$A$200,"<="&'Cumulative Table'!$AG$28) -> 3
D33: WH | E33: EL | F33: =SUMIF('Dữ Liệu'!#REF!,'Cumulative Table'!$X12,'Dữ Liệu'!H8:H139) -> #REF! | G33: =SUMIF('Daily Report'!$AD$7:$AD$263,'Cumulative Table'!$X$7:$X$201&"KIEM",'Daily Report'!$H$7:$H$199) -> 23 | H33: =SUMIF('Daily Report'!$AD$7:$AD$263,'Cumulative Table'!$X$7:$X$201&"TAIKIEM",'Daily Report'!$H$7:$H$263) -> 2 | I33: =SUMIF('Daily Report'!$AE$7:$AE$263,'Cumulative Table'!$X$7:$X$201,'Daily Report'!$I$7:$I$263) -> 23 | J33: =SUMIF('Daily Report'!AE32:AE288,'Cumulative Table'!X33:X226,'Daily Report'!R32:R288) -> 0 | N33: =SUM(K33:M33) -> 0 | O33: =SUMIF('Daily Report'!$AE$7:$AE$199,'Cumulative Table'!$X$7:$X$201,'Daily Report'!$K$7:$K$199) -> 0 | P33: =SUMIF('Daily Report'!$AE$7:$AE$263,'Cumulative Table'!X$7:$X$201,'Daily Report'!$L$7:$L$263) -> 0 | Q33: =SUMIF('Daily Report'!$AE$7:$AE$263,'Cumulative Table'!$X$7:$X$201,'Daily Report'!$M$7:$M$263) -> 0 | R33: =SUMIF('Daily Report'!$AE$7:$AE$263,'Cumulative Table'!$X$7:$X$201,'Daily Report'!$N$7:$N$263) -> 0 | S33: =SUMIF('Daily Report'!$AE$7:$AE$263,'Cumulative Table'!$X$7:$X$201,'Daily Report'!$O$7:$O$263) -> 2 | T33: =SUMIF('Daily Report'!$AE$7:$AE$263,'Cumulative Table'!$X$8:$X$201,'Daily Report'!$P$7:$P$263) -> 0 | U33: =SUMIF('Daily Report'!$AE$7:$AE$263,'Cumulative Table'!$X$7:$X$201,'Daily Report'!$Q$7:$Q$263) -> 0 | W33: =H33/G33 -> 0.086956522 | X33: =$A$28&D33&E33 -> BR9125WHEL | Z33: =SUMIFS('Daily Report'!$H$7:$H$263, 'Daily Report'!$AD$7:$AD$263, $X33&"KIEM", 'Daily Report'!$A$7:$A$263, $Y$28) -> 0 | AB33: =SUMIFS('Daily Report'!$H$7:$H$200,'Daily Report'!$AD$7:$AD$200,'Cumulative Table'!$X33&"KIEM",'Daily Report'!$A$7:$A$200,'Cumulative Table'!$AA$28) -> 0 | AD33: =SUMIFS('Daily Report'!$H$7:$H$200,'Daily Report'!$AD$7:$AD$200,'Cumulative Table'!$X33&"KIEM",'Daily Report'!$A$7:$A$200,'Cumulative Table'!$AC$28) -> 23 | AE33: =SUMIFS('Daily Report'!$H$7:$H$200,'Daily Report'!$AD$7:$AD$200,'Cumulative Table'!$X33&"KIEM",'Daily Report'!$A$7:$A$200,">="&'Cumulative Table'!$Y$28,'Daily Report'!$A$7:$A$200,"<="&'Cumulative Table'!$AC$28) -> 23 | AH33: =SUMIFS('Daily Report'!$H$7:$H$200,'Daily Report'!$AD$7:$AD$200,'Cumulative Table'!$X33&"KIEM",'Daily Report'!$A$7:$A$200,">="&'Cumulative Table'!$AF$28,'Daily Report'!$A$7:$A$200,"<="&'Cumulative Table'!$AG$28) -> 23 | AI33: =SUMIFS('Daily Report'!$H$7:$H$200,'Daily Report'!$AD$7:$AD$200,'Cumulative Table'!$X33&"TAIKIEM",'Daily Report'!$A$7:$A$200,">="&'Cumulative Table'!$AF$28,'Daily Report'!$A$7:$A$200,"<="&'Cumulative Table'!$AG$28) -> 2
D34: WH | E34: 4L | F34: =SUMIF('Dữ Liệu'!#REF!,'Cumulative Table'!$X13,'Dữ Liệu'!H8:H140) -> #REF! | G34: =SUMIF('Daily Report'!$AD$7:$AD$263,'Cumulative Table'!$X$7:$X$201&"KIEM",'Daily Report'!$H$7:$H$199) -> 14 | H34: =SUMIF('Daily Report'!$AD$7:$AD$263,'Cumulative Table'!$X$7:$X$201&"TAIKIEM",'Daily Report'!$H$7:$H$263) -> 1 | I34: =SUMIF('Daily Report'!$AE$7:$AE$263,'Cumulative Table'!$X$7:$X$201,'Daily Report'!$I$7:$I$263) -> 14 | J34: =SUMIF('Daily Report'!AE33:AE289,'Cumulative Table'!X34:X227,'Daily Report'!R33:R289) -> 0 | N34: =SUM(K34:M34) -> 0 | O34: =SUMIF('Daily Report'!$AE$7:$AE$199,'Cumulative Table'!$X$7:$X$201,'Daily Report'!$K$7:$K$199) -> 0 | P34: =SUMIF('Daily Report'!$AE$7:$AE$263,'Cumulative Table'!X$7:$X$201,'Daily Report'!$L$7:$L$263) -> 0 | Q34: =SUMIF('Daily Report'!$AE$7:$AE$263,'Cumulative Table'!$X$7:$X$201,'Daily Report'!$M$7:$M$263) -> 1 | R34: =SUMIF('Daily Report'!$AE$7:$AE$263,'Cumulative Table'!$X$7:$X$201,'Daily Report'!$N$7:$N$263) -> 0 | S34: =SUMIF('Daily Report'!$AE$7:$AE$263,'Cumulative Table'!$X$7:$X$201,'Daily Report'!$O$7:$O$263) -> 0 | T34: =SUMIF('Daily Report'!$AE$7:$AE$263,'Cumulative Table'!$X$8:$X$201,'Daily Report'!$P$7:$P$263) -> 0 | U34: =SUMIF('Daily Report'!$AE$7:$AE$263,'Cumulative Table'!$X$7:$X$201,'Daily Report'!$Q$7:$Q$263) -> 0 | W34: =H34/G34 -> 0.071428571 | X34: =$A$28&D34&E34 -> BR9125WH4L | Z34: =SUMIFS('Daily Report'!$H$7:$H$263, 'Daily Report'!$AD$7:$AD$263, $X34&"KIEM", 'Daily Report'!$A$7:$A$263, $Y$28) -> 0 | AB34: =SUMIFS('Daily Report'!$H$7:$H$200,'Daily Report'!$AD$7:$AD$200,'Cumulative Table'!$X34&"KIEM",'Daily Report'!$A$7:$A$200,'Cumulative Table'!$AA$28) -> 0 | AD34: =SUMIFS('Daily Report'!$H$7:$H$200,'Daily Report'!$AD$7:$AD$200,'Cumulative Table'!$X34&"KIEM",'Daily Report'!$A$7:$A$200,'Cumulative Table'!$AC$28) -> 14 | AE34: =SUMIFS('Daily Report'!$H$7:$H$200,'Daily Report'!$AD$7:$AD$200,'Cumulative Table'!$X34&"KIEM",'Daily Report'!$A$7:$A$200,">="&'Cumulative Table'!$Y$28,'Daily Report'!$A$7:$A$200,"<="&'Cumulative Table'!$AC$28) -> 14 | AH34: =SUMIFS('Daily Report'!$H$7:$H$200,'Daily Report'!$AD$7:$AD$200,'Cumulative Table'!$X34&"KIEM",'Daily Report'!$A$7:$A$200,">="&'Cumulative Table'!$AF$28,'Daily Report'!$A$7:$A$200,"<="&'Cumulative Table'!$AG$28) -> 14 | AI34: =SUMIFS('Daily Report'!$H$7:$H$200,'Daily Report'!$AD$7:$AD$200,'Cumulative Table'!$X34&"TAIKIEM",'Daily Report'!$A$7:$A$200,">="&'Cumulative Table'!$AF$28,'Daily Report'!$A$7:$A$200,"<="&'Cumulative Table'!$AG$28) -> 1
D35: WH | E35: 5L | F35: =SUMIF('Dữ Liệu'!#REF!,'Cumulative Table'!$X14,'Dữ Liệu'!H8:H141) -> #REF! | G35: =SUMIF('Daily Report'!$AD$7:$AD$263,'Cumulative Table'!$X$7:$X$201&"KIEM",'Daily Report'!$H$7:$H$199) -> 13 | H35: =SUMIF('Daily Report'!$AD$7:$AD$263,'Cumulative Table'!$X$7:$X$201&"TAIKIEM",'Daily Report'!$H$7:$H$263) -> 1 | I35: =SUMIF('Daily Report'!$AE$7:$AE$263,'Cumulative Table'!$X$7:$X$201,'Daily Report'!$I$7:$I$263) -> 13 | J35: =SUMIF('Daily Report'!AE34:AE290,'Cumulative Table'!X35:X228,'Daily Report'!R34:R290) -> 0 | N35: =SUM(K35:M35) -> 0 | O35: =SUMIF('Daily Report'!$AE$7:$AE$199,'Cumulative Table'!$X$7:$X$201,'Daily Report'!$K$7:$K$199) -> 0 | P35: =SUMIF('Daily Report'!$AE$7:$AE$263,'Cumulative Table'!X$7:$X$201,'Daily Report'!$L$7:$L$263) -> 0 | Q35: =SUMIF('Daily Report'!$AE$7:$AE$263,'Cumulative Table'!$X$7:$X$201,'Daily Report'!$M$7:$M$263) -> 0 | R35: =SUMIF('Daily Report'!$AE$7:$AE$263,'Cumulative Table'!$X$7:$X$201,'Daily Report'!$N$7:$N$263) -> 0 | S35: =SUMIF('Daily Report'!$AE$7:$AE$263,'Cumulative Table'!$X$7:$X$201,'Daily Report'!$O$7:$O$263) -> 1 | T35: =SUMIF('Daily Report'!$AE$7:$AE$263,'Cumulative Table'!$X$8:$X$201,'Daily Report'!$P$7:$P$263) -> 0 | U35: =SUMIF('Daily Report'!$AE$7:$AE$263,'Cumulative Table'!$X$7:$X$201,'Daily Report'!$Q$7:$Q$263) -> 0 | W35: =H35/G35 -> 0.076923077 | X35: =$A$28&D35&E35 -> BR9125WH5L | Z35: =SUMIFS('Daily Report'!$H$7:$H$263, 'Daily Report'!$AD$7:$AD$263, $X35&"KIEM", 'Daily Report'!$A$7:$A$263, $Y$28) -> 0 | AB35: =SUMIFS('Daily Report'!$H$7:$H$200,'Daily Report'!$AD$7:$AD$200,'Cumulative Table'!$X35&"KIEM",'Daily Report'!$A$7:$A$200,'Cumulative Table'!$AA$28) -> 0 | AD35: =SUMIFS('Daily Report'!$H$7:$H$200,'Daily Report'!$AD$7:$AD$200,'Cumulative Table'!$X35&"KIEM",'Daily Report'!$A$7:$A$200,'Cumulative Table'!$AC$28) -> 13 | AE35: =SUMIFS('Daily Report'!$H$7:$H$200,'Daily Report'!$AD$7:$AD$200,'Cumulative Table'!$X35&"KIEM",'Daily Report'!$A$7:$A$200,">="&'Cumulative Table'!$Y$28,'Daily Report'!$A$7:$A$200,"<="&'Cumulative Table'!$AC$28) -> 13 | AH35: =SUMIFS('Daily Report'!$H$7:$H$200,'Daily Report'!$AD$7:$AD$200,'Cumulative Table'!$X35&"KIEM",'Daily Report'!$A$7:$A$200,">="&'Cumulative Table'!$AF$28,'Daily Report'!$A$7:$A$200,"<="&'Cumulative Table'!$AG$28) -> 13 | AI35: =SUMIFS('Daily Report'!$H$7:$H$200,'Daily Report'!$AD$7:$AD$200,'Cumulative Table'!$X35&"TAIKIEM",'Daily Report'!$A$7:$A$200,">="&'Cumulative Table'!$AF$28,'Daily Report'!$A$7:$A$200,"<="&'Cumulative Table'!$AG$28) -> 1
